{
 "cells": [
  {
   "cell_type": "code",
   "execution_count": 4,
   "metadata": {},
   "outputs": [],
   "source": [
    "import os\n",
    "import numpy as np\n",
    "import phonemizer\n",
    "import librosa.display\n",
    "import matplotlib.pyplot as plt\n",
    "import tensorflow as tf\n",
    "import keras as keras\n",
    "from tensorflow.keras.layers import LSTM, Dense\n",
    "from tensorflow.keras.models import Sequential\n",
    "from tensorflow.keras.optimizers import Adam\n",
    "from tensorflow.keras.losses import MeanSquaredError\n",
    "from nltk.tokenize import word_tokenize"
   ]
  },
  {
   "cell_type": "code",
   "execution_count": 5,
   "metadata": {},
   "outputs": [
    {
     "name": "stdout",
     "output_type": "stream",
     "text": [
      "WARNING:tensorflow:Model was constructed with shape (None, 99, 120) for input KerasTensor(type_spec=TensorSpec(shape=(None, 99, 120), dtype=tf.float32, name='lstm_input'), name='lstm_input', description=\"created by layer 'lstm_input'\"), but it was called on an input with incompatible shape (None,).\n"
     ]
    },
    {
     "ename": "ValueError",
     "evalue": "in user code:\n\n    File \"c:\\Users\\soumy\\miniconda3\\envs\\tf\\lib\\site-packages\\keras\\engine\\training.py\", line 2041, in predict_function  *\n        return step_function(self, iterator)\n    File \"c:\\Users\\soumy\\miniconda3\\envs\\tf\\lib\\site-packages\\keras\\engine\\training.py\", line 2027, in step_function  **\n        outputs = model.distribute_strategy.run(run_step, args=(data,))\n    File \"c:\\Users\\soumy\\miniconda3\\envs\\tf\\lib\\site-packages\\keras\\engine\\training.py\", line 2015, in run_step  **\n        outputs = model.predict_step(data)\n    File \"c:\\Users\\soumy\\miniconda3\\envs\\tf\\lib\\site-packages\\keras\\engine\\training.py\", line 1983, in predict_step\n        return self(x, training=False)\n    File \"c:\\Users\\soumy\\miniconda3\\envs\\tf\\lib\\site-packages\\keras\\utils\\traceback_utils.py\", line 70, in error_handler\n        raise e.with_traceback(filtered_tb) from None\n    File \"c:\\Users\\soumy\\miniconda3\\envs\\tf\\lib\\site-packages\\keras\\engine\\input_spec.py\", line 232, in assert_input_compatibility\n        raise ValueError(\n\n    ValueError: Exception encountered when calling layer \"sequential\" \"                 f\"(type Sequential).\n    \n    Input 0 of layer \"lstm\" is incompatible with the layer: expected ndim=3, found ndim=1. Full shape received: (None,)\n    \n    Call arguments received by layer \"sequential\" \"                 f\"(type Sequential):\n      • inputs=tf.Tensor(shape=(None,), dtype=string)\n      • training=False\n      • mask=None\n",
     "output_type": "error",
     "traceback": [
      "\u001b[1;31m---------------------------------------------------------------------------\u001b[0m",
      "\u001b[1;31mValueError\u001b[0m                                Traceback (most recent call last)",
      "Cell \u001b[1;32mIn[5], line 8\u001b[0m\n\u001b[0;32m      6\u001b[0m input_data \u001b[39m=\u001b[39m word_tokenize(giventext)\n\u001b[0;32m      7\u001b[0m \u001b[39m# Generate predictions\u001b[39;00m\n\u001b[1;32m----> 8\u001b[0m predictions \u001b[39m=\u001b[39m model\u001b[39m.\u001b[39;49mpredict(input_data)\n\u001b[0;32m     11\u001b[0m \u001b[39m# Display or utilize predictions\u001b[39;00m\n\u001b[0;32m     12\u001b[0m \u001b[39mprint\u001b[39m(processed_predictions)\n",
      "File \u001b[1;32mc:\\Users\\soumy\\miniconda3\\envs\\tf\\lib\\site-packages\\keras\\utils\\traceback_utils.py:70\u001b[0m, in \u001b[0;36mfilter_traceback.<locals>.error_handler\u001b[1;34m(*args, **kwargs)\u001b[0m\n\u001b[0;32m     67\u001b[0m     filtered_tb \u001b[39m=\u001b[39m _process_traceback_frames(e\u001b[39m.\u001b[39m__traceback__)\n\u001b[0;32m     68\u001b[0m     \u001b[39m# To get the full stack trace, call:\u001b[39;00m\n\u001b[0;32m     69\u001b[0m     \u001b[39m# `tf.debugging.disable_traceback_filtering()`\u001b[39;00m\n\u001b[1;32m---> 70\u001b[0m     \u001b[39mraise\u001b[39;00m e\u001b[39m.\u001b[39mwith_traceback(filtered_tb) \u001b[39mfrom\u001b[39;00m \u001b[39mNone\u001b[39;00m\n\u001b[0;32m     71\u001b[0m \u001b[39mfinally\u001b[39;00m:\n\u001b[0;32m     72\u001b[0m     \u001b[39mdel\u001b[39;00m filtered_tb\n",
      "File \u001b[1;32m~\\AppData\\Local\\Temp\\__autograph_generated_filendtyea7e.py:15\u001b[0m, in \u001b[0;36mouter_factory.<locals>.inner_factory.<locals>.tf__predict_function\u001b[1;34m(iterator)\u001b[0m\n\u001b[0;32m     13\u001b[0m \u001b[39mtry\u001b[39;00m:\n\u001b[0;32m     14\u001b[0m     do_return \u001b[39m=\u001b[39m \u001b[39mTrue\u001b[39;00m\n\u001b[1;32m---> 15\u001b[0m     retval_ \u001b[39m=\u001b[39m ag__\u001b[39m.\u001b[39mconverted_call(ag__\u001b[39m.\u001b[39mld(step_function), (ag__\u001b[39m.\u001b[39mld(\u001b[39mself\u001b[39m), ag__\u001b[39m.\u001b[39mld(iterator)), \u001b[39mNone\u001b[39;00m, fscope)\n\u001b[0;32m     16\u001b[0m \u001b[39mexcept\u001b[39;00m:\n\u001b[0;32m     17\u001b[0m     do_return \u001b[39m=\u001b[39m \u001b[39mFalse\u001b[39;00m\n",
      "\u001b[1;31mValueError\u001b[0m: in user code:\n\n    File \"c:\\Users\\soumy\\miniconda3\\envs\\tf\\lib\\site-packages\\keras\\engine\\training.py\", line 2041, in predict_function  *\n        return step_function(self, iterator)\n    File \"c:\\Users\\soumy\\miniconda3\\envs\\tf\\lib\\site-packages\\keras\\engine\\training.py\", line 2027, in step_function  **\n        outputs = model.distribute_strategy.run(run_step, args=(data,))\n    File \"c:\\Users\\soumy\\miniconda3\\envs\\tf\\lib\\site-packages\\keras\\engine\\training.py\", line 2015, in run_step  **\n        outputs = model.predict_step(data)\n    File \"c:\\Users\\soumy\\miniconda3\\envs\\tf\\lib\\site-packages\\keras\\engine\\training.py\", line 1983, in predict_step\n        return self(x, training=False)\n    File \"c:\\Users\\soumy\\miniconda3\\envs\\tf\\lib\\site-packages\\keras\\utils\\traceback_utils.py\", line 70, in error_handler\n        raise e.with_traceback(filtered_tb) from None\n    File \"c:\\Users\\soumy\\miniconda3\\envs\\tf\\lib\\site-packages\\keras\\engine\\input_spec.py\", line 232, in assert_input_compatibility\n        raise ValueError(\n\n    ValueError: Exception encountered when calling layer \"sequential\" \"                 f\"(type Sequential).\n    \n    Input 0 of layer \"lstm\" is incompatible with the layer: expected ndim=3, found ndim=1. Full shape received: (None,)\n    \n    Call arguments received by layer \"sequential\" \"                 f\"(type Sequential):\n      • inputs=tf.Tensor(shape=(None,), dtype=string)\n      • training=False\n      • mask=None\n"
     ]
    }
   ],
   "source": [
    "giventext = \"Lets gooooo baby\"\n",
    "\n",
    "model = tf.keras.models.load_model('tts_model2.h5')\n",
    "\n",
    "# Preprocess input data\n",
    "input_data = word_tokenize(giventext)\n",
    "# Generate predictions\n",
    "predictions = model.predict(input_data)\n",
    "\n",
    "\n",
    "# Display or utilize predictions\n",
    "print(processed_predictions)"
   ]
  },
  {
   "cell_type": "code",
   "execution_count": null,
   "metadata": {},
   "outputs": [],
   "source": [
    "def text_to_Inputable(giventext):\n",
    "    tokenized_texts = word_tokenize(giventext)\n",
    "    "
   ]
  }
 ],
 "metadata": {
  "kernelspec": {
   "display_name": "tf",
   "language": "python",
   "name": "python3"
  },
  "language_info": {
   "codemirror_mode": {
    "name": "ipython",
    "version": 3
   },
   "file_extension": ".py",
   "mimetype": "text/x-python",
   "name": "python",
   "nbconvert_exporter": "python",
   "pygments_lexer": "ipython3",
   "version": "3.9.17"
  },
  "orig_nbformat": 4
 },
 "nbformat": 4,
 "nbformat_minor": 2
}
